File: input/temperature.txt
#EXPORTTYPE:DATA ALL

#FILE:MoC desorb Ar 1000C 20Kpm.ngb-sss

#FORMAT:NETZSCH5

#FTYPE:ANSI

#IDENTITY:desorb 1000C

#DECIMAL:POINT

#SEPARATOR:SEMICOLON

#MTYPE:DSC

#INSTRUMENT:NETZSCH STA 409C/CD

#PROJECT:

#DATE/TIME:06.07.2017 10:50

#CORR. FILE:

#TEMPCAL:TCALZERO.TCX

#SENSITIVITY:SENSZERO.EXX

#LABORATORY:

#OPERATOR:

#REMARK:MFC 2 S.P. = 60 SCCM (Ar)  MFC 3 S.P. = 20 SCCM (Ar)

#SAMPLE:MoC SKN 2-14-3

#SAMPLE MASS /mg:80.5

#MATERIAL:

#REFERENCE:

#REFERENCE MASS /mg:0

#TYPE OF CRUCIBLE:DSC/TG pan Al2O3

#SAMPLE CRUCIBLE MASS /mg:166

#REFERENCE CRUCIBLE MASS /mg:0

#GAS 1:AIR(80/20)

#FLOW RATE 1 /(ml/min):0

#GAS 2:ARGON

#FLOW RATE 2 /(ml/min):60

#DSC RANGE /µV:5000

#TG RANGE /mg:50000

#TAU-R:---

#CORR. CODE:000

#EXO:-1

#RANGE:25.0°C....1000.0°C/-99.0....20.0K/min

#SEGMENT:S1-3/3

#SEG. 1:25.0°C/20.0(K/min)/1000.0°C

#SEG. 2:1000.0°C/01:00/1000.0°C

#SEG. 3:1000.0°C/99.0(K/min)/100.0°C



##Temp./°C;Time/min;DSC/uV;Mass/%;Sensit./(uV/mW);Segment

 25.01700;  0.00000;       0.14875;100.00000;1.00000;1

 25.02200;  0.02000;       0.14375;100.00000;1.00000;1

 25.02000;  0.04000;       0.14625;100.00000;1.00000;1

 25.02300;  0.06000;       0.15250;100.00000;1.00000;1

 25.02800;  0.08000;       0.14375;100.00000;1.00000;1

 25.02000;  0.10000;       0.14375;100.00000;1.00000;1

 25.01600;  0.12000;       0.14250;100.00000;1.00000;1

 25.01400;  0.14000;       0.14500;100.00000;1.00000;1

 25.01900;  0.16000;       0.14125;100.00000;1.00000;1

 25.02900;  0.18000;       0.14250;100.00000;1.00000;1

 25.02200;  0.20000;       0.14500;100.00000;1.00000;1

 25.01900;  0.22000;       0.13875;100.00000;1.00000;1

 25.01700;  0.24000;       0.13875;100.00000;1.00000;1

 25.02000;  0.26000;       0.13625; 99.99379;1.00000;1

 25.02500;  0.28000;       0.13000; 99.99379;1.00000;1

 25.01700;  0.30000;       0.13125; 99.99379;1.00000;1

 25.02000;  0.32000;       0.13500; 99.99379;1.00000;1

 25.02300;  0.34000;       0.13500; 99.99379;1.00000;1

 25.02500;  0.36000;       0.13250; 99.99379;1.00000;1

 25.02200;  0.38000;       0.13000; 99.99379;1.00000;1

 25.01300;  0.40000;       0.13250; 99.99379;1.00000;1

 25.01700;  0.42000;       0.12750; 99.99379;1.00000;1

 25.01400;  0.44000;       0.13125; 99.99379;1.00000;1

 25.02300;  0.46000;       0.12875; 99.98758;1.00000;1

 25.02900;  0.48000;       0.12625; 99.98758;1.00000;1

 25.02800;  0.50000;       0.13000; 99.98758;1.00000;1

 25.03700;  0.52000;       0.12625; 99.98758;1.00000;1

 25.03600;  0.54000;       0.12750; 99.98758;1.00000;1

 25.03600;  0.56000;       0.12750; 99.98137;1.00000;1

 25.03200;  0.58000;       0.12750; 99.98137;1.00000;1

 25.04600;  0.60000;       0.12750; 99.98137;1.00000;1

 25.04200;  0.62000;       0.13000; 99.98137;1.00000;1

 25.04200;  0.64000;       0.12500; 99.98137;1.00000;1

 25.03400;  0.66000;       0.12625; 99.98137;1.00000;1

 25.03400;  0.68000;       0.13000; 99.98137;1.00000;1

 25.04200;  0.70000;       0.13000; 99.98137;1.00000;1

 25.04600;  0.72000;       0.13250; 99.98137;1.00000;1

 25.04800;  0.74000;       0.12750; 99.98137;1.00000;1

 25.05500;  0.76000;       0.13500; 99.98137;1.00000;1

 25.05400;  0.78000;       0.13375; 99.98137;1.00000;1

 25.05100;  0.80000;       0.14375; 99.98137;1.00000;1

 25.06400;  0.82000;       0.14000; 99.98758;1.00000;1

 25.07500;  0.84000;       0.14000; 99.98758;1.00000;1

 25.08100;  0.86000;       0.15000; 99.98758;1.00000;1

 25.08700;  0.88000;       0.15250; 99.98758;1.00000;1

 25.09000;  0.90000;       0.16125; 99.98758;1.00000;1

 25.10400;  0.92000;       0.16375; 99.98758;1.00000;1

 25.12200;  0.94000;       0.17125; 99.98758;1.00000;1

 25.13100;  0.96000;       0.17250; 99.99379;1.00000;1

 25.13300;  0.98000;       0.17750; 99.99379;1.00000;1

 25.14300;  1.00000;       0.18375; 99.99379;1.00000;1

 25.16600;  1.02000;       0.18625; 99.99379;1.00000;1

 25.17200;  1.04000;       0.19375; 99.99379;1.00000;1

 25.18000;  1.06000;       0.20125;100.00000;1.00000;1

 25.19900;  1.08000;       0.20625;100.00000;1.00000;1

 25.21500;  1.10000;       0.21750;100.00000;1.00000;1

 25.23900;  1.12000;       0.22875;100.00000;1.00000;1

 25.25400;  1.14000;       0.23250;100.00000;1.00000;1

 25.27100;  1.16000;       0.24250;100.00000;1.00000;1

 25.29200;  1.18000;       0.25125;100.00000;1.00000;1

 25.31000;  1.20000;       0.26125;100.00000;1.00000;1

 25.32800;  1.22000;       0.27500;100.00000;1.00000;1

 25.35600;  1.24000;       0.29000;100.00621;1.00000;1

 25.37100;  1.26000;       0.30375;100.00621;1.00000;1

 25.41000;  1.28000;       0.31250;100.01242;1.00000;1

 25.43800;  1.30000;       0.32875;100.01242;1.00000;1

 25.46800;  1.32000;       0.33625;100.01242;1.00000;1

 25.49700;  1.34000;       0.35750;100.01242;1.00000;1

 25.53000;  1.36000;       0.37125;100.01863;1.00000;1

 25.56300;  1.38000;       0.37875;100.01863;1.00000;1

 25.60100;  1.40000;       0.39750;100.01863;1.00000;1

 25.63200;  1.42000;       0.40875;100.01863;1.00000;1

 25.67400;  1.44000;       0.43125;100.02484;1.00000;1

 25.71600;  1.46000;       0.44625;100.02484;1.00000;1

 25.75700;  1.48000;       0.46625;100.02484;1.00000;1

 25.80100;  1.50000;       0.48625;100.03106;1.00000;1

 25.84500;  1.52000;       0.50125;100.03106;1.00000;1

 25.88000;  1.54000;       0.52000;100.03727;1.00000;1

 25.93000;  1.56000;       0.53750;100.03727;1.00000;1

 25.98100;  1.58000;       0.55875;100.03727;1.00000;1

 26.03100;  1.60000;       0.58000;100.04348;1.00000;1

 26.07400;  1.62000;       0.60125;100.04348;1.00000;1

 26.13100;  1.64000;       0.62500;100.04969;1.00000;1

 26.18900;  1.66000;       0.64000;100.04969;1.00000;1

 26.23500;  1.68000;       0.66750;100.04969;1.00000;1

 26.30200;  1.70000;       0.68875;100.05590;1.00000;1

 26.33800;  1.72000;       0.71250;100.05590;1.00000;1

 26.40600;  1.74000;       0.73375;100.06211;1.00000;1

 26.47600;  1.76000;       0.76250;100.06211;1.00000;1

 26.53500;  1.78000;       0.78125;100.06211;1.00000;1

 26.59300;  1.80000;       0.80875;100.06832;1.00000;1

 26.65500;  1.82000;       0.83750;100.06832;1.00000;1

 26.71700;  1.84000;       0.86500;100.07453;1.00000;1

 26.79400;  1.86000;       0.89000;100.07453;1.00000;1

 26.86200;  1.88000;       0.92000;100.08075;1.00000;1

 26.92200;  1.90000;       0.94750;100.08075;1.00000;1

 26.99300;  1.92000;       0.97750;100.08075;1.00000;1

 27.06400;  1.94000;       1.00750;100.08696;1.00000;1

 27.13600;  1.96000;       1.02750;100.08696;1.00000;1

 27.19800;  1.98000;       1.06375;100.09317;1.00000;1

 27.28100;  2.00000;       1.09250;100.09317;1.00000;1

 27.36200;  2.02000;       1.12125;100.09938;1.00000;1

 27.43500;  2.04000;       1.15500;100.09938;1.00000;1

 27.52000;  2.06000;       1.18375;100.10559;1.00000;1

 27.59700;  2.08000;       1.21875;100.10559;1.00000;1

 27.67800;  2.10000;       1.25000;100.11180;1.00000;1

 27.75700;  2.12000;       1.28250;100.11801;1.00000;1

 27.83900;  2.14000;       1.31125;100.11801;1.00000;1

 27.92600;  2.16000;       1.35000;100.12422;1.00000;1

 28.00500;  2.18000;       1.37750;100.12422;1.00000;1

 28.08700;  2.20000;       1.41875;100.13043;1.00000;1

 28.17300;  2.22000;       1.44125;100.13043;1.00000;1

 28.26000;  2.24000;       1.47875;100.13043;1.00000;1

 28.36200;  2.26000;       1.51125;100.13665;1.00000;1

 28.43400;  2.28000;       1.53750;100.13665;1.00000;1

 28.52400;  2.30000;       1.58125;100.13665;1.00000;1

 28.62600;  2.32000;       1.61000;100.13665;1.00000;1

 28.71700;  2.34000;       1.63875;100.14286;1.00000;1

 28.79800;  2.36000;       1.67250;100.14286;1.00000;1

 28.89700;  2.38000;       1.70375;100.14286;1.00000;1

 28.99100;  2.40000;       1.74125;100.14286;1.00000;1

 29.08600;  2.42000;       1.76500;100.14286;1.00000;1

 29.18700;  2.44000;       1.80125;100.14907;1.00000;1

 29.27400;  2.46000;       1.83500;100.14907;1.00000;1

 29.37400;  2.48000;       1.86125;100.14907;1.00000;1

 29.47400;  2.50000;       1.89750;100.14907;1.00000;1

 29.57300;  2.52000;       1.92875;100.14907;1.00000;1

 29.66900;  2.54000;       1.96125;100.14907;1.00000;1

 29.75800;  2.56000;       1.99625;100.14907;1.00000;1

 29.86600;  2.58000;       2.02375;100.14907;1.00000;1

 29.96100;  2.60000;       2.06000;100.15528;1.00000;1

 30.08200;  2.62000;       2.08375;100.15528;1.00000;1

 30.17900;  2.64000;       2.11625;100.15528;1.00000;1

 30.28600;  2.66000;       2.14875;100.16149;1.00000;1

 30.38000;  2.68000;       2.17500;100.16149;1.00000;1

 30.50200;  2.70000;       2.20500;100.16149;1.00000;1

 30.61100;  2.72000;       2.23875;100.16149;1.00000;1

 30.71200;  2.74000;       2.27250;100.16770;1.00000;1

 30.81600;  2.76000;       2.29625;100.16770;1.00000;1

 30.93500;  2.78000;       2.32625;100.16770;1.00000;1

 31.05000;  2.80000;       2.36500;100.16770;1.00000;1

 31.15700;  2.82000;       2.38875;100.16770;1.00000;1

 31.26200;  2.84000;       2.41875;100.17391;1.00000;1

 31.36900;  2.86000;       2.44375;100.17391;1.00000;1

 31.49700;  2.88000;       2.46625;100.17391;1.00000;1

 31.61400;  2.90000;       2.50125;100.17391;1.00000;1

 31.72100;  2.92000;       2.51625;100.17391;1.00000;1

 31.82900;  2.94000;       2.55250;100.18012;1.00000;1

 31.95700;  2.96000;       2.57875;100.18012;1.00000;1

 32.06900;  2.98000;       2.60500;100.18012;1.00000;1

 32.20400;  3.00000;       2.63625;100.18634;1.00000;1

 32.31500;  3.02000;       2.66250;100.18634;1.00000;1

 32.43800;  3.04000;       2.68250;100.18634;1.00000;1

 32.56500;  3.06000;       2.71250;100.18634;1.00000;1

 32.68000;  3.08000;       2.73125;100.18634;1.00000;1

 32.81300;  3.10000;       2.75750;100.19255;1.00000;1

 32.93700;  3.12000;       2.78125;100.19255;1.00000;1

 33.06200;  3.14000;       2.80500;100.19255;1.00000;1

 33.19300;  3.16000;       2.82875;100.19255;1.00000;1

 33.32100;  3.18000;       2.84875;100.19255;1.00000;1

 33.46300;  3.20000;       2.88375;100.19876;1.00000;1

 33.57600;  3.22000;       2.89750;100.19876;1.00000;1

 33.70900;  3.24000;       2.92250;100.19876;1.00000;1

 33.84500;  3.26000;       2.94875;100.19876;1.00000;1

 33.97600;  3.28000;       2.96250;100.19876;1.00000;1

 34.13000;  3.30000;       2.98625;100.20497;1.00000;1

 34.25500;  3.32000;       3.00750;100.20497;1.00000;1

 34.39800;  3.34000;       3.02250;100.20497;1.00000;1

 34.54200;  3.36000;       3.05000;100.20497;1.00000;1

 34.68300;  3.38000;       3.06625;100.20497;1.00000;1

 34.81500;  3.40000;       3.09375;100.21118;1.00000;1

 34.95300;  3.42000;       3.11250;100.21118;1.00000;1

 35.10500;  3.44000;       3.13125;100.21118;1.00000;1

 35.25200;  3.46000;       3.15500;100.21739;1.00000;1

 35.39700;  3.48000;       3.17625;100.21739;1.00000;1

 35.55200;  3.50000;       3.19250;100.21739;1.00000;1

 35.68700;  3.52000;       3.21000;100.21739;1.00000;1

 35.83800;  3.54000;       3.23500;100.21739;1.00000;1

 35.98700;  3.56000;       3.25250;100.21739;1.00000;1

 36.13800;  3.58000;       3.26750;100.22360;1.00000;1

 36.29000;  3.60000;       3.29500;100.22360;1.00000;1

 36.44000;  3.62000;       3.30875;100.22360;1.00000;1

 36.60100;  3.64000;       3.33250;100.22360;1.00000;1

 36.76400;  3.66000;       3.34625;100.22981;1.00000;1

 36.92000;  3.68000;       3.36500;100.22981;1.00000;1

 37.08200;  3.70000;       3.38875;100.22981;1.00000;1

 37.24800;  3.72000;       3.41000;100.22981;1.00000;1

 37.39200;  3.74000;       3.42750;100.22981;1.00000;1

 37.55700;  3.76000;       3.44250;100.22981;1.00000;1

 37.71200;  3.78000;       3.46625;100.22981;1.00000;1

 37.88400;  3.80000;       3.48375;100.22981;1.00000;1

 38.04500;  3.82000;       3.50625;100.22981;1.00000;1

 38.21800;  3.84000;       3.52125;100.23602;1.00000;1

 38.38600;  3.86000;       3.54125;100.23602;1.00000;1

 38.55800;  3.88000;       3.56375;100.23602;1.00000;1

 38.71900;  3.90000;       3.58250;100.23602;1.00000;1

 38.89800;  3.92000;       3.60000;100.23602;1.00000;1

 39.05600;  3.94000;       3.62125;100.24224;1.00000;1

 39.24000;  3.96000;       3.63500;100.24224;1.00000;1

 39.41500;  3.98000;       3.66125;100.24224;1.00000;1

 39.59000;  4.00000;       3.68000;100.24224;1.00000;1

 39.76800;  4.02000;       3.70375;100.24224;1.00000;1

 39.95300;  4.04000;       3.71750;100.24845;1.00000;1

 40.12700;  4.06000;       3.74750;100.24845;1.00000;1

 40.30500;  4.08000;       3.76500;100.24845;1.00000;1

 40.48800;  4.10000;       3.78125;100.25466;1.00000;1

 40.67300;  4.12000;       3.80250;100.25466;1.00000;1

 40.84500;  4.14000;       3.82375;100.25466;1.00000;1

 41.03800;  4.16000;       3.84125;100.25466;1.00000;1

 41.22300;  4.18000;       3.85875;100.25466;1.00000;1

 41.40200;  4.20000;       3.88250;100.25466;1.00000;1

 41.59600;  4.22000;       3.90625;100.25466;1.00000;1

 41.78000;  4.24000;       3.92250;100.26087;1.00000;1

 41.97100;  4.26000;       3.95000;100.26087;1.00000;1

 42.16500;  4.28000;       3.97250;100.26087;1.00000;1

 42.36400;  4.30000;       3.98625;100.26087;1.00000;1

 42.54500;  4.32000;       4.01125;100.26087;1.00000;1

 42.74600;  4.34000;       4.03375;100.26087;1.00000;1

 42.94100;  4.36000;       4.06125;100.26087;1.00000;1

 43.12900;  4.38000;       4.07875;100.26708;1.00000;1

 43.32600;  4.40000;       4.10000;100.26708;1.00000;1

 43.52400;  4.42000;       4.12125;100.26708;1.00000;1

 43.73000;  4.44000;       4.14250;100.26708;1.00000;1

 43.92400;  4.46000;       4.17375;100.26708;1.00000;1

 44.14200;  4.48000;       4.19375;100.26708;1.00000;1

 44.34300;  4.50000;       4.21375;100.26708;1.00000;1

 44.54400;  4.52000;       4.23875;100.26708;1.00000;1

 44.73900;  4.54000;       4.25500;100.26708;1.00000;1

 44.94700;  4.56000;       4.28375;100.26708;1.00000;1

 45.15700;  4.58000;       4.30000;100.26708;1.00000;1

 45.36600;  4.60000;       4.32250;100.26708;1.00000;1

 45.55600;  4.62000;       4.34000;100.26708;1.00000;1

 45.76900;  4.64000;       4.36875;100.27329;1.00000;1

 45.97600;  4.66000;       4.38500;100.27329;1.00000;1

 46.19000;  4.68000;       4.41375;100.27329;1.00000;1

 46.39600;  4.70000;       4.43250;100.27329;1.00000;1

 46.61100;  4.72000;       4.45750;100.27329;1.00000;1

 46.82700;  4.74000;       4.47750;100.27329;1.00000;1

 47.04500;  4.76000;       4.50625;100.27329;1.00000;1

 47.25300;  4.78000;       4.51625;100.27329;1.00000;1

 47.47700;  4.80000;       4.53750;100.27329;1.00000;1

 47.69300;  4.82000;       4.56500;100.27329;1.00000;1

 47.89700;  4.84000;       4.58625;100.27329;1.00000;1

 48.11700;  4.86000;       4.60500;100.27329;1.00000;1

 48.36500;  4.88000;       4.63375;100.27329;1.00000;1

 48.56200;  4.90000;       4.65125;100.27329;1.00000;1

 48.79300;  4.92000;       4.68000;100.27329;1.00000;1

 49.01500;  4.94000;       4.69125;100.27329;1.00000;1

 49.23600;  4.96000;       4.71250;100.27329;1.00000;1

 49.46200;  4.98000;       4.73500;100.27329;1.00000;1

 49.69000;  5.00000;       4.75625;100.27329;1.00000;1

 49.91000;  5.02000;       4.77375;100.27329;1.00000;1

 50.15000;  5.04000;       4.79375;100.27329;1.00000;1

 50.36300;  5.06000;       4.81375;100.27950;1.00000;1

 50.59000;  5.08000;       4.83375;100.27950;1.00000;1

 50.82400;  5.10000;       4.85625;100.27950;1.00000;1

 51.04800;  5.12000;       4.87500;100.27950;1.00000;1

 51.29100;  5.14000;       4.88875;100.27950;1.00000;1

 51.51000;  5.16000;       4.91000;100.27950;1.00000;1

 51.73800;  5.18000;       4.92625;100.27950;1.00000;1

 51.99400;  5.20000;       4.94750;100.27950;1.00000;1

 52.22600;  5.22000;       4.96000;100.27950;1.00000;1

 52.46500;  5.24000;       4.98000;100.27950;1.00000;1

 52.70400;  5.26000;       4.99750;100.27950;1.00000;1

 52.94800;  5.28000;       5.01125;100.27950;1.00000;1

 53.18300;  5.30000;       5.03250;100.27950;1.00000;1

 53.41700;  5.32000;       5.05500;100.27950;1.00000;1

 53.67300;  5.34000;       5.06875;100.27950;1.00000;1

 53.91600;  5.36000;       5.08625;100.27950;1.00000;1

 54.16000;  5.38000;       5.10000;100.27950;1.00000;1

 54.39800;  5.40000;       5.11125;100.27950;1.00000;1

 54.64200;  5.42000;       5.12875;100.27950;1.00000;1

 54.88700;  5.44000;       5.15125;100.27950;1.00000;1

 55.13200;  5.46000;       5.16375;100.27950;1.00000;1

 55.39400;  5.48000;       5.18125;100.27950;1.00000;1

 55.64800;  5.50000;       5.19250;100.27950;1.00000;1

 55.87800;  5.52000;       5.21500;100.27950;1.00000;1

 56.13700;  5.54000;       5.22375;100.27950;1.00000;1

 56.39500;  5.56000;       5.24625;100.27950;1.00000;1

 56.64600;  5.58000;       5.25750;100.27950;1.00000;1

 56.90100;  5.60000;       5.27125;100.27950;1.00000;1

 57.15100;  5.62000;       5.28875;100.27950;1.00000;1

 57.42600;  5.64000;       5.30250;100.27950;1.00000;1

 57.67100;  5.66000;       5.31875;100.27950;1.00000;1

 57.94200;  5.68000;       5.32625;100.27950;1.00000;1

 58.17700;  5.70000;       5.34750;100.27329;1.00000;1

 58.45000;  5.72000;       5.36125;100.27329;1.00000;1

 58.70400;  5.74000;       5.37500;100.27329;1.00000;1

 58.96200;  5.76000;       5.38750;100.27329;1.00000;1

 59.25200;  5.78000;       5.40375;100.27329;1.00000;1

 59.50000;  5.80000;       5.41875;100.27329;1.00000;1

 59.76500;  5.82000;       5.42875;100.27329;1.00000;1

 60.02300;  5.84000;       5.43500;100.27329;1.00000;1

 60.28600;  5.86000;       5.45125;100.27329;1.00000;1

 60.55400;  5.88000;       5.46500;100.27329;1.00000;1

 60.82700;  5.90000;       5.47750;100.27329;1.00000;1

 61.09600;  5.92000;       5.49125;100.27329;1.00000;1

 61.37700;  5.94000;       5.50250;100.27329;1.00000;1

 61.63900;  5.96000;       5.52125;100.26708;1.00000;1

 61.91800;  5.98000;       5.53000;100.26708;1.00000;1

 62.18600;  6.00000;       5.54500;100.26708;1.00000;1

 62.46400;  6.02000;       5.56125;100.26708;1.00000;1

 62.74300;  6.04000;       5.56875;100.26708;1.00000;1

 63.02200;  6.06000;       5.57625;100.26708;1.00000;1

 63.30200;  6.08000;       5.58500;100.26708;1.00000;1

 63.58200;  6.10000;       5.60375;100.26708;1.00000;1

 63.86600;  6.12000;       5.61250;100.26708;1.00000;1

 64.13800;  6.14000;       5.62625;100.26708;1.00000;1

 64.41500;  6.16000;       5.64500;100.26708;1.00000;1

 64.70700;  6.18000;       5.64875;100.26708;1.00000;1

 64.98900;  6.20000;       5.66625;100.26708;1.00000;1

 65.27500;  6.22000;       5.67125;100.26087;1.00000;1

 65.55100;  6.24000;       5.68375;100.26087;1.00000;1

 65.83900;  6.26000;       5.69375;100.26087;1.00000;1

 66.13300;  6.28000;       5.70000;100.26087;1.00000;1

 66.40800;  6.30000;       5.71250;100.26087;1.00000;1

 66.69900;  6.32000;       5.72000;100.26087;1.00000;1

 66.98900;  6.34000;       5.73125;100.25466;1.00000;1

 67.27700;  6.36000;       5.74500;100.25466;1.00000;1

 67.57700;  6.38000;       5.74750;100.25466;1.00000;1

 67.86400;  6.40000;       5.75875;100.25466;1.00000;1

 68.15700;  6.42000;       5.76375;100.25466;1.00000;1

 68.44700;  6.44000;       5.77625;100.25466;1.00000;1

 68.73000;  6.46000;       5.78375;100.24845;1.00000;1

 69.03100;  6.48000;       5.79500;100.24845;1.00000;1

 69.31800;  6.50000;       5.80000;100.24845;1.00000;1

 69.62800;  6.52000;       5.80875;100.24845;1.00000;1

 69.92100;  6.54000;       5.81375;100.24845;1.00000;1

 70.21700;  6.56000;       5.81500;100.24845;1.00000;1

 70.51000;  6.58000;       5.83000;100.24224;1.00000;1

 70.80800;  6.60000;       5.83500;100.24224;1.00000;1

 71.10300;  6.62000;       5.84125;100.24224;1.00000;1

 71.39400;  6.64000;       5.84875;100.24224;1.00000;1

 71.71700;  6.66000;       5.84875;100.23602;1.00000;1

 72.00500;  6.68000;       5.86000;100.23602;1.00000;1

 72.31200;  6.70000;       5.86125;100.23602;1.00000;1

 72.60700;  6.72000;       5.86375;100.23602;1.00000;1

 72.92200;  6.74000;       5.86750;100.22981;1.00000;1

 73.23800;  6.76000;       5.87250;100.22981;1.00000;1

 73.53600;  6.78000;       5.87875;100.22981;1.00000;1

 73.83700;  6.80000;       5.88000;100.22981;1.00000;1

 74.13300;  6.82000;       5.88500;100.22981;1.00000;1

 74.44900;  6.84000;       5.88000;100.22360;1.00000;1

 74.75400;  6.86000;       5.88625;100.22360;1.00000;1

 75.06600;  6.88000;       5.88500;100.22360;1.00000;1

 75.38200;  6.90000;       5.88250;100.22360;1.00000;1

 75.68900;  6.92000;       5.88000;100.21739;1.00000;1

 75.99400;  6.94000;       5.88125;100.21739;1.00000;1

 76.30700;  6.96000;       5.88000;100.21739;1.00000;1

 76.63100;  6.98000;       5.88125;100.21118;1.00000;1

 76.93100;  7.00000;       5.87500;100.21118;1.00000;1

 77.24700;  7.02000;       5.86875;100.21118;1.00000;1

 77.56800;  7.04000;       5.87125;100.21118;1.00000;1

 77.89000;  7.06000;       5.86625;100.20497;1.00000;1

 78.21100;  7.08000;       5.86250;100.20497;1.00000;1

 78.51100;  7.10000;       5.86125;100.20497;1.00000;1

 78.83900;  7.12000;       5.85250;100.20497;1.00000;1

 79.15700;  7.14000;       5.84375;100.19876;1.00000;1

 79.47500;  7.16000;       5.83750;100.19876;1.00000;1

 79.78900;  7.18000;       5.83125;100.19876;1.00000;1

 80.11900;  7.20000;       5.82625;100.19255;1.00000;1

 80.44300;  7.22000;       5.81750;100.19255;1.00000;1

 80.77400;  7.24000;       5.80875;100.19255;1.00000;1

 81.08500;  7.26000;       5.79750;100.19255;1.00000;1

 81.41200;  7.28000;       5.78500;100.18634;1.00000;1

 81.73600;  7.30000;       5.77375;100.18634;1.00000;1

 82.05900;  7.32000;       5.77000;100.18634;1.00000;1

 82.39500;  7.34000;       5.75250;100.18012;1.00000;1

 82.72700;  7.36000;       5.73625;100.18012;1.00000;1

 83.04400;  7.38000;       5.72000;100.18012;1.00000;1

 83.37400;  7.40000;       5.71250;100.18012;1.00000;1

 83.71200;  7.42000;       5.69875;100.18012;1.00000;1

 84.04800;  7.44000;       5.67625;100.18012;1.00000;1

 84.37900;  7.46000;       5.66750;100.17391;1.00000;1

 84.71200;  7.48000;       5.64625;100.17391;1.00000;1

 85.04300;  7.50000;       5.62500;100.17391;1.00000;1

 85.37600;  7.52000;       5.61500;100.17391;1.00000;1

 85.72300;  7.54000;       5.59875;100.17391;1.00000;1

 86.06100;  7.56000;       5.57500;100.16770;1.00000;1

 86.39500;  7.58000;       5.56000;100.16770;1.00000;1

 86.74200;  7.60000;       5.53875;100.16770;1.00000;1

 87.07800;  7.62000;       5.52125;100.16770;1.00000;1

 87.41400;  7.64000;       5.49875;100.16149;1.00000;1

 87.74900;  7.66000;       5.46875;100.16149;1.00000;1

 88.08600;  7.68000;       5.44875;100.16149;1.00000;1

 88.45000;  7.70000;       5.41875;100.15528;1.00000;1

 88.78800;  7.72000;       5.40125;100.15528;1.00000;1

 89.13600;  7.74000;       5.37500;100.15528;1.00000;1

 89.46500;  7.76000;       5.35375;100.15528;1.00000;1

 89.81100;  7.78000;       5.32125;100.15528;1.00000;1

 90.15800;  7.80000;       5.29375;100.15528;1.00000;1

 90.51000;  7.82000;       5.27000;100.14907;1.00000;1

 90.86300;  7.84000;       5.24375;100.14907;1.00000;1

 91.21800;  7.86000;       5.21000;100.14907;1.00000;1

 91.54900;  7.88000;       5.18500;100.14286;1.00000;1

 91.91100;  7.90000;       5.15750;100.14286;1.00000;1

 92.26100;  7.92000;       5.12125;100.14286;1.00000;1

 92.60600;  7.94000;       5.09125;100.13665;1.00000;1

 92.95900;  7.96000;       5.06000;100.13665;1.00000;1

 93.33300;  7.98000;       5.02125;100.13665;1.00000;1

 93.67300;  8.00000;       4.99750;100.13043;1.00000;1

 94.04300;  8.02000;       4.95875;100.13043;1.00000;1

 94.40300;  8.04000;       4.93250;100.13043;1.00000;1

 94.75100;  8.06000;       4.88875;100.13043;1.00000;1

 95.11200;  8.08000;       4.85875;100.12422;1.00000;1

 95.47000;  8.10000;       4.82375;100.12422;1.00000;1

 95.82100;  8.12000;       4.78250;100.12422;1.00000;1

 96.19400;  8.14000;       4.74750;100.12422;1.00000;1

 96.55900;  8.16000;       4.71375;100.11801;1.00000;1

 96.92000;  8.18000;       4.68125;100.11801;1.00000;1

 97.26400;  8.20000;       4.63625;100.11801;1.00000;1

 97.63400;  8.22000;       4.60375;100.11801;1.00000;1

 97.99300;  8.24000;       4.56250;100.11180;1.00000;1

 98.37700;  8.26000;       4.51750;100.11180;1.00000;1

 98.74100;  8.28000;       4.47875;100.11180;1.00000;1

 99.10100;  8.30000;       4.43875;100.11180;1.00000;1

 99.46900;  8.32000;       4.39500;100.11180;1.00000;1

 99.84800;  8.34000;       4.35125;100.11180;1.00000;1

100.21100;  8.36000;       4.31750;100.11180;1.00000;1

100.58500;  8.38000;       4.27250;100.10559;1.00000;1

100.93900;  8.40000;       4.22875;100.10559;1.00000;1

101.28600;  8.42000;       4.18375;100.10559;1.00000;1

101.67900;  8.44000;       4.14000;100.10559;1.00000;1

102.05300;  8.46000;       4.09750;100.09938;1.00000;1

102.41900;  8.48000;       4.05125;100.09938;1.00000;1

102.79000;  8.50000;       4.00875;100.09938;1.00000;1

103.16200;  8.52000;       3.96125;100.09317;1.00000;1

103.53400;  8.54000;       3.91125;100.09317;1.00000;1

103.90700;  8.56000;       3.87250;100.09317;1.00000;1

104.28300;  8.58000;       3.82250;100.09317;1.00000;1

104.65000;  8.60000;       3.78250;100.09317;1.00000;1

105.04700;  8.62000;       3.72750;100.08696;1.00000;1

105.40300;  8.64000;       3.66875;100.08696;1.00000;1

105.78300;  8.66000;       3.61625;100.08696;1.00000;1

106.16900;  8.68000;       3.57625;100.08696;1.00000;1

106.54500;  8.70000;       3.52750;100.08696;1.00000;1

106.92300;  8.72000;       3.47500;100.08075;1.00000;1

107.29700;  8.74000;       3.42500;100.08075;1.00000;1

107.67700;  8.76000;       3.37000;100.08075;1.00000;1

108.05900;  8.78000;       3.31750;100.08075;1.00000;1

108.44400;  8.80000;       3.26750;100.08075;1.00000;1

108.82500;  8.82000;       3.20750;100.08075;1.00000;1

109.19700;  8.84000;       3.15500;100.08075;1.00000;1

109.58200;  8.86000;       3.10250;100.07453;1.00000;1

109.97400;  8.88000;       3.04875;100.07453;1.00000;1

110.35200;  8.90000;       2.98375;100.07453;1.00000;1

110.73000;  8.92000;       2.93625;100.07453;1.00000;1

111.12000;  8.94000;       2.88125;100.06832;1.00000;1

111.49900;  8.96000;       2.83000;100.06832;1.00000;1

111.89900;  8.98000;       2.76625;100.06832;1.00000;1

112.27900;  9.00000;       2.71125;100.06832;1.00000;1

112.65300;  9.02000;       2.65625;100.06832;1.00000;1

113.05100;  9.04000;       2.59000;100.06832;1.00000;1

113.43800;  9.06000;       2.54625;100.06211;1.00000;1

113.83700;  9.08000;       2.47875;100.06211;1.00000;1

114.22000;  9.10000;       2.43000;100.06211;1.00000;1

114.61100;  9.12000;       2.37375;100.06211;1.00000;1

115.00500;  9.14000;       2.31375;100.06211;1.00000;1

115.38500;  9.16000;       2.25500;100.05590;1.00000;1

115.78100;  9.18000;       2.19750;100.05590;1.00000;1

116.18700;  9.20000;       2.13875;100.05590;1.00000;1

116.56600;  9.22000;       2.08250;100.05590;1.00000;1

116.95600;  9.24000;       2.01250;100.05590;1.00000;1

117.36200;  9.26000;       1.96375;100.05590;1.00000;1

117.74900;  9.28000;       1.90375;100.05590;1.00000;1

118.13400;  9.30000;       1.84750;100.05590;1.00000;1

118.53300;  9.32000;       1.79125;100.04969;1.00000;1

118.91500;  9.34000;       1.72875;100.04969;1.00000;1

119.32600;  9.36000;       1.67250;100.04969;1.00000;1

119.71700;  9.38000;       1.61500;100.04969;1.00000;1

120.11800;  9.40000;       1.55250;100.04348;1.00000;1

120.53300;  9.42000;       1.49750;100.04348;1.00000;1

120.92700;  9.44000;       1.43875;100.04348;1.00000;1

121.31700;  9.46000;       1.38000;100.04348;1.00000;1

121.72400;  9.48000;       1.32250;100.04348;1.00000;1

122.11300;  9.50000;       1.26500;100.04348;1.00000;1

122.51800;  9.52000;       1.20000;100.04348;1.00000;1

122.91900;  9.54000;       1.14500;100.04348;1.00000;1

123.32300;  9.56000;       1.08375;100.03727;1.00000;1

123.72500;  9.58000;       1.01750;100.03727;1.00000;1

124.13100;  9.60000;       0.96375;100.03727;1.00000;1

124.53100;  9.62000;       0.90500;100.03727;1.00000;1

124.94300;  9.64000;       0.84750;100.03106;1.00000;1

125.33400;  9.66000;       0.79000;100.03106;1.00000;1

125.74400;  9.68000;       0.72875;100.03106;1.00000;1

126.16700;  9.70000;       0.66750;100.03106;1.00000;1

126.56000;  9.72000;       0.60875;100.02484;1.00000;1

126.95900;  9.74000;       0.54875;100.02484;1.00000;1

127.37900;  9.76000;       0.49250;100.02484;1.00000;1

127.78100;  9.78000;       0.43875;100.02484;1.00000;1

128.19299;  9.80000;       0.36875;100.02484;1.00000;1

128.60400;  9.82000;       0.31500;100.02484;1.00000;1

129.00600;  9.84000;       0.25000;100.02484;1.00000;1

129.40800;  9.86000;       0.19000;100.02484;1.00000;1

129.82899;  9.88000;       0.13000;100.02484;1.00000;1

130.23399;  9.90000; 7.500004e-002;100.01863;1.00000;1

130.65300;  9.92000; 1.125001e-002;100.01863;1.00000;1

131.06700;  9.94000;-4.625002e-002;100.01863;1.00000;1

131.47701;  9.96000;      -0.10500;100.01863;1.00000;1

131.89600;  9.98000;      -0.16250;100.01863;1.00000;1

132.31200; 10.00000;      -0.23625;100.01863;1.00000;1

132.70900; 10.02000;      -0.28875;100.01242;1.00000;1

133.11800; 10.04000;      -0.35500;100.01242;1.00000;1

133.55499; 10.06000;      -0.42125;100.01242;1.00000;1

133.97501; 10.08000;      -0.48500;100.01242;1.00000;1

134.38300; 10.10000;      -0.55125;100.01242;1.00000;1

134.80200; 10.12000;      -0.60375;100.01242;1.00000;1

135.22301; 10.14000;      -0.66250;100.01242;1.00000;1

135.64400; 10.16000;      -0.73875;100.01242;1.00000;1

136.06100; 10.18000;      -0.79625;100.00621;1.00000;1

136.47800; 10.20000;      -0.86625;100.00621;1.00000;1

136.89500; 10.22000;      -0.92250;100.00621;1.00000;1

137.30600; 10.24000;      -0.99000;100.00621;1.00000;1

137.73700; 10.26000;      -1.06125;100.00621;1.00000;1

138.17599; 10.28000;      -1.12250;100.00621;1.00000;1

138.58299; 10.30000;      -1.18375;100.00621;1.00000;1

139.01401; 10.32000;      -1.25375;100.00621;1.00000;1

139.45300; 10.34000;      -1.31125;100.00000;1.00000;1

139.86600; 10.36000;      -1.37625;100.00000;1.00000;1

140.29100; 10.38000;      -1.44625;100.00000;1.00000;1

140.70700; 10.40000;      -1.50875;100.00000;1.00000;1

141.14200; 10.42000;      -1.57750;100.00000;1.00000;1

141.57100; 10.44000;      -1.64500; 99.99379;1.00000;1

141.98599; 10.46000;      -1.70875; 99.99379;1.00000;1

142.41100; 10.48000;      -1.76875; 99.99379;1.00000;1

142.85201; 10.50000;      -1.83875; 99.99379;1.00000;1

143.29500; 10.52000;      -1.90375; 99.99379;1.00000;1

143.70200; 10.54000;      -1.97250; 99.99379;1.00000;1

144.13100; 10.56000;      -2.03625; 99.98758;1.00000;1

144.56599; 10.58000;      -2.09750; 99.98758;1.00000;1

144.98900; 10.60000;      -2.15875; 99.98758;1.00000;1

145.42599; 10.62000;      -2.23375; 99.98758;1.00000;1

145.85400; 10.64000;      -2.29875; 99.98758;1.00000;1

146.28400; 10.66000;      -2.36125; 99.98758;1.00000;1

146.73000; 10.68000;      -2.43125; 99.98758;1.00000;1

147.16000; 10.70000;      -2.50125; 99.98758;1.00000;1

147.60899; 10.72000;      -2.56625; 99.98137;1.00000;1

148.01700; 10.74000;      -2.63750; 99.98137;1.00000;1

148.45500; 10.76000;      -2.70375; 99.98137;1.00000;1

148.90199; 10.78000;      -2.76750; 99.98137;1.00000;1

149.32300; 10.80000;      -2.83375; 99.98137;1.00000;1

149.75301; 10.82000;      -2.89625; 99.97516;1.00000;1

150.18500; 10.84000;      -2.96125; 99.97516;1.00000;1

150.62801; 10.86000;      -3.03750; 99.97516;1.00000;1

151.07500; 10.88000;      -3.11000; 99.97516;1.00000;1

151.50999; 10.90000;      -3.17125; 99.97516;1.00000;1

151.94701; 10.92000;      -3.24125; 99.97516;1.00000;1

152.38400; 10.94000;      -3.30500; 99.97516;1.00000;1

152.82201; 10.96000;      -3.37000; 99.97516;1.00000;1

153.25500; 10.98000;      -3.44500; 99.97516;1.00000;1

153.69501; 11.00000;      -3.50375; 99.97516;1.00000;1

154.12801; 11.02000;      -3.58250; 99.97516;1.00000;1

154.56500; 11.04000;      -3.64500; 99.97516;1.00000;1

155.00900; 11.06000;      -3.71750; 99.97516;1.00000;1

155.45900; 11.08000;      -3.78750; 99.97516;1.00000;1

155.89799; 11.10000;      -3.84500; 99.97516;1.00000;1

156.32700; 11.12000;      -3.92250; 99.97516;1.00000;1

156.78799; 11.14000;      -3.98625; 99.97516;1.00000;1

157.21899; 11.16000;      -4.05500; 99.96894;1.00000;1

157.66299; 11.18000;      -4.13000; 99.96894;1.00000;1

158.09500; 11.20000;      -4.20625; 99.96894;1.00000;1

158.53900; 11.22000;      -4.27250; 99.96894;1.00000;1

158.97701; 11.24000;      -4.34500; 99.96894;1.00000;1

159.42900; 11.26000;      -4.41250; 99.96894;1.00000;1

159.86700; 11.28000;      -4.48250; 99.96894;1.00000;1

160.32700; 11.30000;      -4.55250; 99.96273;1.00000;1

160.76199; 11.32000;      -4.62625; 99.96273;1.00000;1

161.20500; 11.34000;      -4.70250; 99.96273;1.00000;1

161.64799; 11.36000;      -4.77500; 99.96273;1.00000;1

162.09399; 11.38000;      -4.84375; 99.95652;1.00000;1

162.54300; 11.40000;      -4.92125; 99.95652;1.00000;1

162.98300; 11.42000;      -4.99500; 99.95652;1.00000;1

163.43300; 11.44000;      -5.06250; 99.95652;1.00000;1

163.87300; 11.46000;      -5.14625; 99.95652;1.00000;1

164.31900; 11.48000;      -5.21875; 99.95031;1.00000;1

164.77200; 11.50000;      -5.29875; 99.95031;1.00000;1

165.21800; 11.52000;      -5.36875; 99.95031;1.00000;1

165.65700; 11.54000;      -5.45125; 99.95031;1.00000;1

166.10400; 11.56000;      -5.52500; 99.94410;1.00000;1

166.55701; 11.58000;      -5.60625; 99.94410;1.00000;1

167.00101; 11.60000;      -5.68125; 99.94410;1.00000;1

167.45000; 11.62000;      -5.76875; 99.93789;1.00000;1

167.89700; 11.64000;      -5.84250; 99.93789;1.00000;1

168.34700; 11.66000;      -5.92250; 99.93789;1.00000;1

168.80701; 11.68000;      -5.99875; 99.93789;1.00000;1

169.25700; 11.70000;      -6.08250; 99.93789;1.00000;1

169.69501; 11.72000;      -6.16250; 99.93789;1.00000;1

170.13699; 11.74000;      -6.24000; 99.93168;1.00000;1

170.59599; 11.76000;      -6.32375; 99.93168;1.00000;1

171.04900; 11.78000;      -6.41250; 99.93168;1.00000;1

171.50101; 11.80000;      -6.49500; 99.93168;1.00000;1

171.95300; 11.82000;      -6.58625; 99.93168;1.00000;1

172.41200; 11.84000;      -6.66750; 99.93168;1.00000;1

172.85300; 11.86000;      -6.75125; 99.93168;1.00000;1

173.30000; 11.88000;      -6.84000; 99.93168;1.00000;1

173.74500; 11.90000;      -6.92125; 99.93168;1.00000;1

174.20000; 11.92000;      -7.01250; 99.93168;1.00000;1

174.66100; 11.94000;      -7.10000; 99.93168;1.00000;1

175.10300; 11.96000;      -7.19625; 99.93168;1.00000;1

175.56799; 11.98000;      -7.27875; 99.93168;1.00000;1

176.02499; 12.00000;      -7.36500; 99.92547;1.00000;1

176.46700; 12.02000;      -7.46875; 99.92547;1.00000;1

176.93201; 12.04000;      -7.55625; 99.92547;1.00000;1

177.39000; 12.06000;      -7.64125; 99.92547;1.00000;1

177.84200; 12.08000;      -7.73875; 99.91925;1.00000;1

178.29700; 12.10000;      -7.82875; 99.91925;1.00000;1

178.75900; 12.12000;      -7.93375; 99.91925;1.00000;1

179.20700; 12.14000;      -8.02250; 99.91925;1.00000;1

179.65900; 12.16000;      -8.11625; 99.91925;1.00000;1

180.12000; 12.18000;      -8.21125; 99.91925;1.00000;1

180.59801; 12.20000;      -8.30875; 99.91304;1.00000;1

181.04800; 12.22000;      -8.40125; 99.91304;1.00000;1

181.49100; 12.24000;      -8.51375; 99.91304;1.00000;1

181.94701; 12.26000;      -8.60625; 99.91304;1.00000;1

182.41299; 12.28000;      -8.70500; 99.90683;1.00000;1

182.87801; 12.30000;      -8.80500; 99.90683;1.00000;1

183.32100; 12.32000;      -8.91000; 99.90683;1.00000;1

183.80400; 12.34000;      -9.00625; 99.90683;1.00000;1

184.25800; 12.36000;      -9.11000; 99.90062;1.00000;1

184.72000; 12.38000;      -9.21875; 99.90062;1.00000;1

185.16499; 12.40000;      -9.31500; 99.90062;1.00000;1

185.63901; 12.42000;      -9.42750; 99.90062;1.00000;1

186.09900; 12.44000;      -9.53500; 99.89441;1.00000;1

186.55499; 12.46000;      -9.63375; 99.89441;1.00000;1

187.02499; 12.48000;      -9.74625; 99.89441;1.00000;1

187.49001; 12.50000;      -9.86001; 99.89441;1.00000;1

187.94701; 12.52000;      -9.96751; 99.88820;1.00000;1

188.39600; 12.54000;     -10.07500; 99.88820;1.00000;1

188.87801; 12.56000;     -10.18126; 99.88820;1.00000;1

189.33400; 12.58000;     -10.29000; 99.88820;1.00000;1

189.80099; 12.60000;     -10.41001; 99.88199;1.00000;1

190.27699; 12.62000;     -10.52001; 99.88199;1.00000;1

190.72501; 12.64000;     -10.63626; 99.88199;1.00000;1

191.20000; 12.66000;     -10.74251; 99.88199;1.00000;1

191.66299; 12.68000;     -10.85501; 99.88199;1.00000;1

192.12300; 12.70000;     -10.96626; 99.87578;1.00000;1

192.59200; 12.72000;     -11.08126; 99.87578;1.00000;1

193.05499; 12.74000;     -11.20626; 99.87578;1.00000;1

193.51900; 12.76000;     -11.32001; 99.87578;1.00000;1

193.99300; 12.78000;     -11.44376; 99.86957;1.00000;1

194.45599; 12.80000;     -11.55251; 99.86957;1.00000;1

194.92700; 12.82000;     -11.67376; 99.86957;1.00000;1

195.39101; 12.84000;     -11.78751; 99.86335;1.00000;1

195.84500; 12.86000;     -11.92126; 99.86335;1.00000;1

196.31799; 12.88000;     -12.02876; 99.86335;1.00000;1

196.80000; 12.90000;     -12.15001; 99.86335;1.00000;1

197.25301; 12.92000;     -12.26751; 99.85714;1.00000;1

197.72701; 12.94000;     -12.38126; 99.85714;1.00000;1

198.19600; 12.96000;     -12.50626; 99.85093;1.00000;1

198.66299; 12.98000;     -12.63376; 99.85093;1.00000;1

199.13800; 13.00000;     -12.75501; 99.85093;1.00000;1

199.61600; 13.02000;     -12.87376; 99.85093;1.00000;1

200.08299; 13.04000;     -12.98501; 99.84472;1.00000;1

200.54601; 13.06000;     -13.11001; 99.84472;1.00000;1

201.02699; 13.08000;     -13.23001; 99.83851;1.00000;1

201.48801; 13.10000;     -13.35626; 99.83851;1.00000;1

201.97400; 13.12000;     -13.47626; 99.83230;1.00000;1

202.43500; 13.14000;     -13.59501; 99.83230;1.00000;1

202.89900; 13.16000;     -13.72001; 99.83230;1.00000;1

203.36800; 13.18000;     -13.83751; 99.82609;1.00000;1

203.84200; 13.20000;     -13.96501; 99.82609;1.00000;1

204.31500; 13.22000;     -14.07626; 99.82609;1.00000;1

204.79201; 13.24000;     -14.20126; 99.82609;1.00000;1

205.25800; 13.26000;     -14.31626; 99.82609;1.00000;1

205.73900; 13.28000;     -14.44876; 99.82609;1.00000;1

206.19800; 13.30000;     -14.56751; 99.82609;1.00000;1

206.67500; 13.32000;     -14.69376; 99.82609;1.00000;1

207.14900; 13.34000;     -14.80626; 99.81988;1.00000;1

207.63200; 13.36000;     -14.92376; 99.81988;1.00000;1

208.09700; 13.38000;     -15.05126; 99.81988;1.00000;1

208.58701; 13.40000;     -15.16876; 99.81366;1.00000;1

209.05299; 13.42000;     -15.28876; 99.81366;1.00000;1

209.51500; 13.44000;     -15.41376; 99.81366;1.00000;1

210.00400; 13.46000;     -15.52876; 99.80745;1.00000;1

210.47099; 13.48000;     -15.65126; 99.80745;1.00000;1

210.94400; 13.50000;     -15.76626; 99.80745;1.00000;1

211.42000; 13.52000;     -15.88001; 99.80124;1.00000;1

211.89301; 13.54000;     -16.00626; 99.80124;1.00000;1

212.37500; 13.56000;     -16.11751; 99.80124;1.00000;1

212.84000; 13.58000;     -16.23751; 99.79503;1.00000;1

213.29800; 13.60000;     -16.35626; 99.79503;1.00000;1

213.78101; 13.62000;     -16.46626; 99.78882;1.00000;1

214.25999; 13.64000;     -16.58876; 99.78882;1.00000;1

214.73801; 13.66000;     -16.69626; 99.78882;1.00000;1

215.21500; 13.68000;     -16.80751; 99.78261;1.00000;1

215.69400; 13.70000;     -16.92501; 99.78261;1.00000;1

216.15900; 13.72000;     -17.03501; 99.77640;1.00000;1

216.63699; 13.74000;     -17.14251; 99.77640;1.00000;1

217.11900; 13.76000;     -17.26251; 99.77019;1.00000;1

217.57700; 13.78000;     -17.36876; 99.77019;1.00000;1

218.06700; 13.80000;     -17.47751; 99.76398;1.00000;1

218.55600; 13.82000;     -17.58626; 99.76398;1.00000;1

219.00900; 13.84000;     -17.69376; 99.75776;1.00000;1

219.49300; 13.86000;     -17.80251; 99.75776;1.00000;1

219.96600; 13.88000;     -17.91751; 99.75155;1.00000;1

220.43900; 13.90000;     -18.02251; 99.75155;1.00000;1

[...]

888.77100;110.68000;      45.27002; 84.70807;1.00000;3

887.76501;110.70000;      45.33502; 84.70807;1.00000;3

886.73602;110.72000;      45.39627; 84.70807;1.00000;3

885.72699;110.74000;      45.44127; 84.70807;1.00000;3

884.72601;110.76000;      45.48627; 84.70807;1.00000;3

883.69299;110.78000;      45.53752; 84.70807;1.00000;3

882.67700;110.80000;      45.57377; 84.70807;1.00000;3

881.67401;110.82000;      45.61877; 84.70807;1.00000;3

880.66101;110.84000;      45.64252; 84.70807;1.00000;3

879.65100;110.86000;      45.67127; 84.70807;1.00000;3

878.66901;110.88000;      45.70127; 84.70807;1.00000;3

877.65601;110.90000;      45.72002; 84.70807;1.00000;3

876.65302;110.92000;      45.74252; 84.70807;1.00000;3

875.65601;110.94000;      45.76252; 84.70807;1.00000;3

874.65698;110.96000;      45.77627; 84.70807;1.00000;3

873.65198;110.98000;      45.79002; 84.70807;1.00000;3

872.65802;111.00000;      45.79752; 84.70807;1.00000;3

871.67902;111.02000;      45.81252; 84.70807;1.00000;3

870.68500;111.04000;      45.82002; 84.70807;1.00000;3

869.69800;111.06000;      45.82002; 84.70807;1.00000;3

868.71997;111.08000;      45.82627; 84.70807;1.00000;3

867.72400;111.10000;      45.82502; 84.70807;1.00000;3

866.75500;111.12000;      45.81377; 84.70807;1.00000;3

865.77100;111.14000;      45.81002; 84.70807;1.00000;3

864.78802;111.16000;      45.80127; 84.70807;1.00000;3

863.81702;111.18000;      45.79502; 84.70807;1.00000;3

862.83301;111.20000;      45.77877; 84.70807;1.00000;3

861.87598;111.22000;      45.76877; 84.70807;1.00000;3

860.89398;111.24000;      45.75752; 84.70807;1.00000;3

859.94800;111.26000;      45.74127; 84.70807;1.00000;3

858.96698;111.28000;      45.72002; 84.70807;1.00000;3

858.00403;111.30000;      45.69877; 84.70807;1.00000;3

857.03497;111.32000;      45.67877; 84.70807;1.00000;3

856.09003;111.34000;      45.64752; 84.70807;1.00000;3

855.12299;111.36000;      45.62752; 84.70807;1.00000;3

854.17102;111.38000;      45.60377; 84.70807;1.00000;3

853.20300;111.40000;      45.56377; 84.70807;1.00000;3

852.25702;111.42000;      45.54002; 84.70807;1.00000;3

851.31299;111.44000;      45.50127; 84.70807;1.00000;3

850.36499;111.46000;      45.47252; 84.70807;1.00000;3

849.43103;111.48000;      45.44127; 84.70807;1.00000;3

848.47601;111.50000;      45.40627; 84.70807;1.00000;3

847.53198;111.52000;      45.37002; 84.70807;1.00000;3

846.59601;111.54000;      45.33377; 84.70807;1.00000;3

845.65802;111.56000;      45.28877; 84.70807;1.00000;3

844.72400;111.58000;      45.25752; 84.70807;1.00000;3

843.79303;111.60000;      45.21752; 84.70807;1.00000;3

842.86499;111.62000;      45.17377; 84.70807;1.00000;3

841.92902;111.64000;      45.12752; 84.70807;1.00000;3

840.95398;111.66000;      44.51627; 84.70807;1.00000;3

840.02100;111.68000;      44.34627; 84.70807;1.00000;3

839.10199;111.70000;      44.28252; 84.70807;1.00000;3

838.18903;111.72000;      44.23002; 84.70807;1.00000;3

837.26898;111.74000;      44.15752; 84.70807;1.00000;3

836.33600;111.76000;      44.11002; 84.70807;1.00000;3

835.42902;111.78000;      44.05627; 84.70186;1.00000;3

834.52197;111.80000;      43.99627; 84.70186;1.00000;3

833.61798;111.82000;      43.93627; 84.70186;1.00000;3

832.71100;111.84000;      43.89127; 84.70186;1.00000;3

831.80298;111.86000;      43.83127; 84.70186;1.00000;3

830.88800;111.88000;      43.76377; 84.70186;1.00000;3

829.97803;111.90000;      43.71127; 84.70186;1.00000;3

829.08002;111.92000;      43.65377; 84.70186;1.00000;3

828.18402;111.94000;      43.59127; 84.70186;1.00000;3

827.28302;111.96000;      43.53502; 84.70186;1.00000;3

826.39801;111.98000;      43.46502; 84.70807;1.00000;3

825.50299;112.00000;      43.41127; 84.70807;1.00000;3

824.62299;112.02000;      43.35252; 84.70807;1.00000;3

823.72601;112.04000;      43.29752; 84.70807;1.00000;3

822.85498;112.06000;      43.23377; 84.70807;1.00000;3

821.96600;112.08000;      43.17252; 84.70807;1.00000;3

821.08698;112.10000;      43.10252; 84.70807;1.00000;3

820.21600;112.12000;      43.04502; 84.70807;1.00000;3

819.33099;112.14000;      42.98127; 84.70807;1.00000;3

818.45398;112.16000;      42.92252; 84.70807;1.00000;3

817.58197;112.18000;      42.85752; 84.70807;1.00000;3

816.72101;112.20000;      42.79502; 84.70186;1.00000;3

815.84100;112.22000;      42.73627; 84.70186;1.00000;3

814.98102;112.24000;      42.67377; 84.70186;1.00000;3

814.12097;112.26000;      42.60627; 84.70186;1.00000;3

813.24597;112.28000;      42.54377; 84.70186;1.00000;3

812.38702;112.30000;      42.47752; 84.70186;1.00000;3

811.52399;112.32000;      42.41127; 84.70186;1.00000;3

810.68298;112.34000;      42.35252; 84.70186;1.00000;3

809.81598;112.36000;      42.28627; 84.70186;1.00000;3

808.97302;112.38000;      42.22502; 84.70186;1.00000;3

808.13702;112.40000;      42.16127; 84.70186;1.00000;3

807.27502;112.42000;      42.09877; 84.70186;1.00000;3

806.42999;112.44000;      42.02627; 84.70186;1.00000;3

805.57800;112.46000;      41.96377; 84.70186;1.00000;3

804.73700;112.48000;      41.89502; 84.70186;1.00000;3

803.90399;112.50000;      41.83252; 84.70186;1.00000;3

803.06000;112.52000;      41.76627; 84.70186;1.00000;3

802.22998;112.54000;      41.70627; 84.70186;1.00000;3

801.40002;112.56000;      41.63877; 84.70186;1.00000;3

800.55499;112.58000;      41.57002; 84.70186;1.00000;3

799.72601;112.60000;      41.50252; 84.70186;1.00000;3

798.90100;112.62000;      41.44252; 84.70186;1.00000;3

798.05103;112.64000;      41.37502; 84.70186;1.00000;3

797.24500;112.66000;      41.31252; 84.70186;1.00000;3

796.41199;112.68000;      41.24502; 84.70186;1.00000;3

795.59003;112.70000;      41.17877; 84.70186;1.00000;3

794.78601;112.72000;      41.11252; 84.70186;1.00000;3

793.95502;112.74000;      41.05252; 84.70186;1.00000;3

793.14203;112.76000;      40.98627; 84.70186;1.00000;3

792.33002;112.78000;      40.91502; 84.70186;1.00000;3

791.52002;112.80000;      40.84752; 84.70186;1.00000;3

790.69897;112.82000;      40.78252; 84.70186;1.00000;3

789.89203;112.84000;      40.71127; 84.70186;1.00000;3

789.09399;112.86000;      40.64502; 84.70186;1.00000;3

788.27002;112.88000;      40.57377; 84.70186;1.00000;3

787.46997;112.90000;      40.50877; 84.70186;1.00000;3

786.67603;112.92000;      40.43627; 84.70186;1.00000;3

785.87000;112.94000;      40.37752; 84.70186;1.00000;3

785.08698;112.96000;      40.30252; 84.70186;1.00000;3

784.27600;112.98000;      40.24127; 84.70186;1.00000;3

783.47900;113.00000;      40.16752; 84.70186;1.00000;3

782.69000;113.02000;      40.10377; 84.70186;1.00000;3

781.91302;113.04000;      40.03752; 84.70186;1.00000;3

781.09998;113.06000;      39.96377; 84.70186;1.00000;3

780.33301;113.08000;      39.90002; 84.70186;1.00000;3

779.53302;113.10000;      39.83252; 84.70186;1.00000;3

778.75500;113.12000;      39.76877; 84.70186;1.00000;3

777.96997;113.14000;      39.69252; 84.70186;1.00000;3

777.17401;113.16000;      39.63377; 84.70186;1.00000;3

776.40198;113.18000;      39.56127; 84.70186;1.00000;3

775.62097;113.20000;      39.49502; 84.70186;1.00000;3

774.85303;113.22000;      39.42877; 84.70186;1.00000;3

774.07703;113.24000;      39.35877; 84.70186;1.00000;3

773.28400;113.26000;      39.28627; 84.70186;1.00000;3

772.50800;113.28000;      39.23002; 84.70186;1.00000;3

771.76501;113.30000;      39.16002; 84.70186;1.00000;3

770.98499;113.32000;      39.09127; 84.70186;1.00000;3

770.21698;113.34000;      39.02127; 84.70186;1.00000;3

769.46301;113.36000;      38.96002; 84.70186;1.00000;3

768.70300;113.38000;      38.89377; 84.70186;1.00000;3

767.92700;113.40000;      38.82627; 84.70186;1.00000;3

767.15399;113.42000;      38.75752; 84.70186;1.00000;3

766.40399;113.44000;      38.69252; 84.70186;1.00000;3

765.63898;113.46000;      38.62877; 84.70186;1.00000;3

764.87500;113.48000;      38.55877; 84.70186;1.00000;3

764.13397;113.50000;      38.49002; 84.70186;1.00000;3

763.37598;113.52000;      38.42002; 84.70186;1.00000;3

762.63898;113.54000;      38.36002; 84.70186;1.00000;3

761.88202;113.56000;      38.29377; 84.70186;1.00000;3

761.12000;113.58000;      38.22502; 84.70186;1.00000;3

760.38202;113.60000;      38.15002; 84.70186;1.00000;3

759.64099;113.62000;      38.09002; 84.70186;1.00000;3

758.88898;113.64000;      38.02627; 84.70186;1.00000;3

758.15997;113.66000;      37.95502; 84.70186;1.00000;3

757.41498;113.68000;      37.89627; 84.70186;1.00000;3

756.66998;113.70000;      37.82377; 84.70186;1.00000;3

755.94098;113.72000;      37.75627; 84.70186;1.00000;3

755.20502;113.74000;      37.68252; 84.70186;1.00000;3

754.47400;113.76000;      37.61877; 84.70186;1.00000;3

753.71997;113.78000;      37.55002; 84.70186;1.00000;3

752.98602;113.80000;      37.48377; 84.70186;1.00000;3

752.25598;113.82000;      37.41502; 84.70186;1.00000;3

751.53302;113.84000;      37.35377; 84.70186;1.00000;3

750.81702;113.86000;      37.28377; 84.70186;1.00000;3

750.08801;113.88000;      37.22252; 84.70186;1.00000;3

749.36200;113.90000;      37.14752; 84.70186;1.00000;3

748.64398;113.92000;      37.08377; 84.70186;1.00000;3

747.92200;113.94000;      37.02127; 84.70186;1.00000;3

747.20300;113.96000;      36.96002; 84.70186;1.00000;3

746.47400;113.98000;      36.89127; 84.70186;1.00000;3

745.75800;114.00000;      36.82377; 84.70186;1.00000;3

745.04498;114.02000;      36.75877; 84.70186;1.00000;3

744.32599;114.04000;      36.70002; 84.70186;1.00000;3

743.61298;114.06000;      36.62752; 84.70186;1.00000;3

742.90100;114.08000;      36.55752; 84.70186;1.00000;3

742.19098;114.10000;      36.50627; 84.70186;1.00000;3

741.49103;114.12000;      36.43502; 84.70186;1.00000;3

740.77301;114.14000;      36.37127; 84.70186;1.00000;3

740.05798;114.16000;      36.30502; 84.70186;1.00000;3

739.35602;114.18000;      36.23877; 84.70186;1.00000;3

738.66302;114.20000;      36.17502; 84.70186;1.00000;3

737.95398;114.22000;      36.11252; 84.70186;1.00000;3

737.23999;114.24000;      36.03627; 84.70186;1.00000;3

736.54102;114.26000;      35.98127; 84.70186;1.00000;3

735.84998;114.28000;      35.92377; 84.70186;1.00000;3

735.14697;114.30000;      35.85127; 84.70186;1.00000;3

734.45801;114.32000;      35.78877; 84.70186;1.00000;3

733.76001;114.34000;      35.72377; 84.70186;1.00000;3

733.06000;114.36000;      35.65877; 84.70186;1.00000;3

732.37598;114.38000;      35.60252; 84.70186;1.00000;3

731.68201;114.40000;      35.53752; 84.70186;1.00000;3

730.98700;114.42000;      35.46752; 84.70186;1.00000;3

730.29700;114.44000;      35.40377; 84.70186;1.00000;3

729.61798;114.46000;      35.34377; 84.69565;1.00000;3

728.93103;114.48000;      35.27752; 84.69565;1.00000;3

728.24402;114.50000;      35.21877; 84.69565;1.00000;3

727.55298;114.52000;      35.15002; 84.69565;1.00000;3

726.86401;114.54000;      35.08502; 84.69565;1.00000;3

726.18597;114.56000;      35.02627; 84.69565;1.00000;3

725.51300;114.58000;      34.96252; 84.69565;1.00000;3

724.83197;114.60000;      34.90002; 84.69565;1.00000;3

724.15802;114.62000;      34.83627; 84.69565;1.00000;3

723.48901;114.64000;      34.77127; 84.69565;1.00000;3

722.81097;114.66000;      34.71752; 84.69565;1.00000;3

722.14099;114.68000;      34.65502; 84.69565;1.00000;3

721.46002;114.70000;      34.58127; 84.69565;1.00000;3

720.78101;114.72000;      34.52127; 84.69565;1.00000;3

720.11200;114.74000;      34.46502; 84.69565;1.00000;3

719.44501;114.76000;      34.40127; 84.69565;1.00000;3

718.78302;114.78000;      34.33752; 84.69565;1.00000;3

718.10999;114.80000;      34.28377; 84.69565;1.00000;3

717.44501;114.82000;      34.21877; 84.69565;1.00000;3

716.77899;114.84000;      34.15377; 84.69565;1.00000;3

716.11102;114.86000;      34.09252; 84.69565;1.00000;3

715.46802;114.88000;      34.03752; 84.69565;1.00000;3

714.80402;114.90000;      33.97127; 84.69565;1.00000;3

714.14301;114.92000;      33.91377; 84.69565;1.00000;3

713.48102;114.94000;      33.84502; 84.69565;1.00000;3

712.82098;114.96000;      33.79127; 84.69565;1.00000;3

712.17499;114.98000;      33.73002; 84.69565;1.00000;3

711.50897;115.00000;      33.66752; 84.69565;1.00000;3

710.85303;115.02000;      33.60252; 84.69565;1.00000;3

710.20697;115.04000;      33.54502; 84.69565;1.00000;3

709.56000;115.06000;      33.48877; 84.69565;1.00000;3

708.88898;115.08000;      33.41877; 84.69565;1.00000;3

708.24799;115.10000;      33.36752; 84.69565;1.00000;3

707.60797;115.12000;      33.30377; 84.69565;1.00000;3

706.95099;115.14000;      33.24377; 84.69565;1.00000;3

706.30103;115.16000;      33.18002; 84.69565;1.00000;3

705.66803;115.18000;      33.12252; 84.69565;1.00000;3

705.03198;115.20000;      33.06002; 84.69565;1.00000;3

704.37097;115.22000;      33.00127; 84.69565;1.00000;3

703.75098;115.24000;      32.94627; 84.69565;1.00000;3

703.09802;115.26000;      32.88626; 84.69565;1.00000;3

702.45801;115.28000;      32.81877; 84.69565;1.00000;3

701.81000;115.30000;      32.76377; 84.69565;1.00000;3

701.17603;115.32000;      32.70752; 84.69565;1.00000;3

700.55103;115.34000;      32.64752; 84.69565;1.00000;3

699.92297;115.36000;      32.58502; 84.69565;1.00000;3

699.29401;115.38000;      32.52752; 84.69565;1.00000;3

698.65302;115.40000;      32.47002; 84.69565;1.00000;3

698.01501;115.42000;      32.40877; 84.69565;1.00000;3

697.38599;115.44000;      32.34752; 84.69565;1.00000;3

696.74799;115.46000;      32.28876; 84.69565;1.00000;3

696.12402;115.48000;      32.24126; 84.69565;1.00000;3

695.49402;115.50000;      32.16627; 84.69565;1.00000;3

694.87799;115.52000;      32.11251; 84.69565;1.00000;3

694.25098;115.54000;      32.06252; 84.69565;1.00000;3

693.63098;115.56000;      31.99377; 84.69565;1.00000;3

693.00098;115.58000;      31.93752; 84.69565;1.00000;3

692.38397;115.60000;      31.88002; 84.69565;1.00000;3

691.76801;115.62000;      31.81627; 84.69565;1.00000;3

691.13000;115.64000;      31.76877; 84.69565;1.00000;3

690.51801;115.66000;      31.70752; 84.69565;1.00000;3

689.89301;115.68000;      31.65502; 84.69565;1.00000;3

689.28101;115.70000;      31.58751; 84.69565;1.00000;3

688.67798;115.72000;      31.53502; 84.69565;1.00000;3

688.06097;115.74000;      31.47377; 84.69565;1.00000;3

687.44702;115.76000;      31.41127; 84.69565;1.00000;3

686.82599;115.78000;      31.35627; 84.69565;1.00000;3

686.21100;115.80000;      31.30127; 84.69565;1.00000;3

685.60999;115.82000;      31.25252; 84.69565;1.00000;3

685.00299;115.84000;      31.19252; 84.69565;1.00000;3

684.38202;115.86000;      31.13002; 84.69565;1.00000;3

683.77899;115.88000;      31.07376; 84.69565;1.00000;3

683.17798;115.90000;      31.02752; 84.68944;1.00000;3

682.56702;115.92000;      30.96377; 84.68944;1.00000;3

681.96802;115.94000;      30.90751; 84.68944;1.00000;3

681.36102;115.96000;      30.84377; 84.68944;1.00000;3

680.76599;115.98000;      30.79002; 84.68944;1.00000;3

680.15802;116.00000;      30.74002; 84.68944;1.00000;3

679.54602;116.02000;      30.67752; 84.68944;1.00000;3

678.95203;116.04000;      30.62752; 84.68944;1.00000;3

678.37201;116.06000;      30.56502; 84.68944;1.00000;3

677.75897;116.08000;      30.50126; 84.68944;1.00000;3

677.16498;116.10000;      30.44876; 84.68944;1.00000;3

676.58099;116.12000;      30.39502; 84.68944;1.00000;3

675.97803;116.14000;      30.34002; 84.68944;1.00000;3

675.38501;116.16000;      30.29127; 84.68944;1.00000;3

674.78302;116.18000;      30.23127; 84.68944;1.00000;3

674.19000;116.20000;      30.17377; 84.68944;1.00000;3

673.59998;116.22000;      30.11752; 84.68944;1.00000;3

673.01300;116.24000;      30.06877; 84.68944;1.00000;3

672.41998;116.26000;      30.01126; 84.68944;1.00000;3

671.82300;116.28000;      29.96001; 84.68944;1.00000;3

671.24597;116.30000;      29.90001; 84.68944;1.00000;3

670.65302;116.32000;      29.83876; 84.68944;1.00000;3

670.06897;116.34000;      29.78752; 84.68944;1.00000;3

669.49200;116.36000;      29.73252; 84.68944;1.00000;3

668.91602;116.38000;      29.67126; 84.68944;1.00000;3

668.32800;116.40000;      29.62502; 84.68944;1.00000;3

667.72601;116.42000;      29.56376; 84.68944;1.00000;3

667.16302;116.44000;      29.51126; 84.68944;1.00000;3

666.57703;116.46000;      29.45877; 84.68944;1.00000;3

665.99597;116.48000;      29.39877; 84.68944;1.00000;3

665.41998;116.50000;      29.34752; 84.68944;1.00000;3

664.82397;116.52000;      29.29127; 84.68944;1.00000;3

664.25299;116.54000;      29.24002; 84.68944;1.00000;3

663.69501;116.56000;      29.17626; 84.68944;1.00000;3

663.11298;116.58000;      29.13126; 84.68944;1.00000;3

662.53101;116.60000;      29.07252; 84.68944;1.00000;3

661.95398;116.62000;      29.02876; 84.68944;1.00000;3

661.39301;116.64000;      28.97126; 84.68944;1.00000;3

660.80798;116.66000;      28.91501; 84.68944;1.00000;3

660.25598;116.68000;      28.86127; 84.68944;1.00000;3

659.69098;116.70000;      28.80751; 84.68323;1.00000;3

659.10400;116.72000;      28.75126; 84.68323;1.00000;3

658.53699;116.74000;      28.70126; 84.68323;1.00000;3

657.97601;116.76000;      28.64751; 84.68323;1.00000;3

657.40198;116.78000;      28.59501; 84.68323;1.00000;3

656.83197;116.80000;      28.54251; 84.68323;1.00000;3

656.27899;116.82000;      28.48627; 84.68323;1.00000;3

655.71698;116.84000;      28.44001; 84.68323;1.00000;3

655.14502;116.86000;      28.37877; 84.68323;1.00000;3

654.59302;116.88000;      28.33001; 84.68323;1.00000;3

654.02301;116.90000;      28.27251; 84.68323;1.00000;3

653.46100;116.92000;      28.22001; 84.68323;1.00000;3

652.90302;116.94000;      28.17626; 84.68323;1.00000;3

652.34698;116.96000;      28.12501; 84.68323;1.00000;3

651.79303;116.98000;      28.06126; 84.68323;1.00000;3

651.23102;117.00000;      28.01251; 84.68323;1.00000;3

650.66498;117.02000;      27.96501; 84.68323;1.00000;3

650.12097;117.04000;      27.90751; 84.68323;1.00000;3

649.56000;117.06000;      27.86126; 84.68323;1.00000;3

649.01703;117.08000;      27.79376; 84.68323;1.00000;3

648.44897;117.10000;      27.74876; 84.68323;1.00000;3

647.90302;117.12000;      27.70376; 84.68323;1.00000;3

647.35999;117.14000;      27.64876; 84.68323;1.00000;3

646.79303;117.16000;      27.59001; 84.68323;1.00000;3

646.25098;117.18000;      27.54376; 84.68323;1.00000;3

645.69800;117.20000;      27.48626; 84.68323;1.00000;3

645.14801;117.22000;      27.43626; 84.68323;1.00000;3

644.60699;117.24000;      27.39626; 84.68323;1.00000;3

644.05902;117.26000;      27.33501; 84.68323;1.00000;3

643.50403;117.28000;      27.29001; 84.68323;1.00000;3

642.96002;117.30000;      27.23376; 84.68323;1.00000;3

642.42999;117.32000;      27.18501; 84.68323;1.00000;3

641.87903;117.34000;      27.13126; 84.68323;1.00000;3

641.34100;117.36000;      27.07876; 84.68323;1.00000;3

640.79303;117.38000;      27.03626; 84.68323;1.00000;3

640.24799;117.40000;      26.98626; 84.68323;1.00000;3

639.71600;117.42000;      26.93251; 84.68323;1.00000;3

639.17700;117.44000;      26.87876; 84.68323;1.00000;3

638.63898;117.46000;      26.83126; 84.68323;1.00000;3

638.10101;117.48000;      26.77251; 84.68323;1.00000;3

637.56403;117.50000;      26.72626; 84.68323;1.00000;3

637.02698;117.52000;      26.67751; 84.68323;1.00000;3

636.49298;117.54000;      26.62876; 84.68323;1.00000;3

635.95099;117.56000;      26.56876; 84.68323;1.00000;3

635.41901;117.58000;      26.52251; 84.68323;1.00000;3

634.87500;117.60000;      26.47876; 84.68323;1.00000;3

634.35303;117.62000;      26.42501; 84.68323;1.00000;3

633.82300;117.64000;      26.36876; 84.68323;1.00000;3

633.29602;117.66000;      26.32626; 84.68323;1.00000;3

632.74902;117.68000;      26.27376; 84.68323;1.00000;3

632.23199;117.70000;      26.23251; 84.68323;1.00000;3

631.71002;117.72000;      26.17876; 84.68323;1.00000;3

631.15302;117.74000;      26.13376; 84.68323;1.00000;3

630.63599;117.76000;      26.07626; 84.68323;1.00000;3

630.10400;117.78000;      26.02251; 84.68323;1.00000;3

629.58899;117.80000;      25.97876; 84.68323;1.00000;3